<?xml version="1.0" ?>
<!-- =================================================================================== -->
<!-- |    This document was autogenerated by xacro from src/auv_manipulator/urdf/manipulator.urdf.xacro | -->
<!-- |    EDITING THIS FILE BY HAND IS NOT RECOMMENDED                                 | -->
<!-- =================================================================================== -->
<robot name="r2d2">
  <link name="base_link"/>
  <link name="odom"/>
  <joint name="base_joint" type="fixed">
    <origin rpy="0 0 0" xyz="0 0 0"/>
    <parent link="base_link"/>
    <child link="odom"/>
  </joint>
  <joint name="base_odom" type="fixed">
    <origin rpy="0 0 0" xyz="0 0 0"/>
    <parent link="odom"/>
    <child link="axis"/>
  </joint>
  <link name="axis">
    <visual>
      <origin rpy="1.57 0 0" xyz="0 0 0"/>
      <geometry>
        <cylinder length=".5" radius="0.01"/>
      </geometry>
      <material name="gray">
        <color rgba=".2 .2 .2 1"/>
      </material>
    </visual>
    <collision>
      <origin rpy="1.57 0 0" xyz="0 0 0"/>
      <geometry>
        <cylinder length=".5" radius="0.01"/>
      </geometry>
      <contact_coefficients kd="1.0" kp="1000.0" mu="0"/>
    </collision>
  </link>
  <link name="leg1">
    <inertial>
      <mass value="1"/>
      <inertia ixx="1e-3" ixy="0" ixz="0" iyy="1e-3" iyz="0" izz="1e-3"/>
      <origin/>
    </inertial>
    <visual>
      <origin xyz="0 0 -.3"/>
      <geometry>
        <box size=".20 .10 .8"/>
      </geometry>
      <material name="white">
        <color rgba="1 1 1 1"/>
      </material>
    </visual>
    <collision>
      <origin xyz="0 0 -.3"/>
      <geometry>
        <box size=".20 .10 .8"/>
      </geometry>
      <contact_coefficients kd="1.0" kp="1000.0" mu="0"/>
    </collision>
  </link>
  <joint name="leg1connect" type="fixed">
    <origin xyz="0 .30 0"/>
    <parent link="axis"/>
    <child link="leg1"/>
  </joint>
  <link name="leg2">
    <inertial>
      <mass value="1"/>
      <inertia ixx="1e-3" ixy="0" ixz="0" iyy="1e-3" iyz="0" izz="1e-3"/>
      <origin/>
    </inertial>
    <visual>
      <origin xyz="0 0 -.3"/>
      <geometry>
        <box size=".20 .10 .8"/>
      </geometry>
      <material name="white">
        <color rgba="1 1 1 1"/>
      </material>
    </visual>
    <collision>
      <origin xyz="0 0 -.3"/>
      <geometry>
        <box size=".20 .10 .8"/>
      </geometry>
      <contact_coefficients kd="1.0" kp="1000.0" mu="0"/>
    </collision>
  </link>
  <joint name="leg2connect" type="fixed">
    <origin xyz="0 -.30 0"/>
    <parent link="axis"/>
    <child link="leg2"/>
  </joint>
  <link name="body">
    <inertial>
      <mass value="1"/>
      <inertia ixx="1e-3" ixy="0" ixz="0" iyy="1e-3" iyz="0" izz="1e-3"/>
      <origin/>
    </inertial>
    <visual>
      <origin xyz="0 0 -0.2"/>
      <geometry>
        <cylinder length=".6" radius=".20"/>
      </geometry>
      <material name="white"/>
    </visual>
    <collision>
      <origin xyz="0 0 0.2"/>
      <geometry>
        <cylinder length=".6" radius=".20"/>
      </geometry>
      <contact_coefficients kd="1.0" kp="1000.0" mu="0"/>
    </collision>
  </link>
  <joint name="tilt" type="revolute">
    <parent link="axis"/>
    <child link="body"/>
    <origin rpy="0 0 0" xyz="0 0 0"/>
    <axis xyz="0 1 0"/>
    <limit effort="10" lower="-.5" upper="0" velocity="10"/>
  </joint>
  <link name="head">
    <inertial>
      <mass value="1"/>
      <inertia ixx="1e-3" ixy="0" ixz="0" iyy="1e-3" iyz="0" izz="1e-3"/>
      <origin/>
    </inertial>
    <visual>
      <geometry>
        <sphere radius=".4"/>
      </geometry>
      <material name="white"/>
    </visual>
    <collision>
      <origin/>
      <geometry>
        <sphere radius=".4"/>
      </geometry>
      <contact_coefficients kd="1.0" kp="1000.0" mu="0"/>
    </collision>
  </link>
  <joint name="swivel" type="continuous">
    <origin xyz="0 0 0.1"/>
    <axis xyz="0 0 1"/>
    <parent link="body"/>
    <child link="head"/>
  </joint>
  <link name="rod">
    <inertial>
      <mass value="1"/>
      <inertia ixx="1e-3" ixy="0" ixz="0" iyy="1e-3" iyz="0" izz="1e-3"/>
      <origin/>
    </inertial>
    <visual>
      <origin xyz="0 0 -.1"/>
      <geometry>
        <cylinder length=".2" radius=".02"/>
      </geometry>
      <material name="gray"/>
    </visual>
    <collision>
      <origin/>
      <geometry>
        <cylinder length=".2" radius=".02"/>
      </geometry>
      <contact_coefficients kd="1.0" kp="1000.0" mu="0"/>
    </collision>
  </link>
  <joint name="periscope" type="prismatic">
    <origin xyz=".12 0 .15"/>
    <axis xyz="0 0 1"/>
    <limit effort="10" lower="-.5" upper="0" velocity="10"/>
    <parent link="head"/>
    <child link="rod"/>
  </joint>
  <link name="box">
    <inertial>
      <mass value="1"/>
      <inertia ixx="1e-3" ixy="0" ixz="0" iyy="1e-3" iyz="0" izz="1e-3"/>
      <origin/>
    </inertial>
    <visual>
      <geometry>
        <box size=".05 .05 .05"/>
      </geometry>
      <material name="blue">
        <color rgba="0 0 1 1"/>
      </material>
    </visual>
    <collision>
      <origin/>
      <geometry>
        <box size=".05 .05 .05"/>
      </geometry>
      <contact_coefficients kd="1.0" kp="1000.0" mu="0"/>
    </collision>
  </link>
  <joint name="boxconnect" type="fixed">
    <origin xyz="0 0 0"/>
    <parent link="rod"/>
    <child link="box"/>
  </joint>
</robot>
